Workbook

Sheet train
A1: Row ID | B1: Order ID | C1: Order Date | D1: Ship Date | E1: Ship Mode | F1: Customer ID | G1: Customer Name | H1: Segment | I1: Country | J1: City | K1: State | L1: Postal Code | M1: Region | N1: Product ID | O1: Category | P1: Sub-Category | Q1: Product Name | R1: Sales
A2: 1 | B2: CA-2017-152156 | C2: 43047 | D2: 43050 | E2: Second Class | F2: CG-12520 | G2: Claire Gute | H2: Consumer | I2: United States | J2: Henderson | K2: Kentucky | L2: 42420 | M2: South | N2: FUR-BO-10001798 | O2: Furniture | P2: Bookcases | Q2: Bush Somerset Collection Bookcase | R2: 261.96
A3: 2 | B3: CA-2017-152156 | C3: 43047 | D3: 43050 | E3: Second Class | F3: CG-12520 | G3: Claire Gute | H3: Consumer | I3: United States | J3: Henderson | K3: Kentucky | L3: 42420 | M3: South | N3: FUR-CH-10000454 | O3: Furniture | P3: Chairs | Q3: Hon Deluxe Fabric Upholstered Stacking Chairs, Rounded Back | R3: 731.94
A4: 3 | B4: CA-2017-138688 | C4: 42898 | D4: 42902 | E4: Second Class | F4: DV-13045 | G4: Darrin Van Huff | H4: Corporate | I4: United States | J4: Los Angeles | K4: California | L4: 90036 | M4: West | N4: OFF-LA-10000240 | O4: Office Supplies | P4: Labels | Q4: Self-Adhesive Address Labels for Typewriters by Universal | R4: 14.62
A5: 4 | B5: US-2016-108966 | C5: 42654 | D5: 42661 | E5: Standard Class | F5: SO-20335 | G5: Sean O'Donnell | H5: Consumer | I5: United States | J5: Fort Lauderdale | K5: Florida | L5: 33311 | M5: South | N5: FUR-TA-10000577 | O5: Furniture | P5: Tables | Q5: Bretford CR4500 Series Slim Rectangular Table | R5: 957.5775
A6: 5 | B6: US-2016-108966 | C6: 42654 | D6: 42661 | E6: Standard Class | F6: SO-20335 | G6: Sean O'Donnell | H6: Consumer | I6: United States | J6: Fort Lauderdale | K6: Florida | L6: 33311 | M6: South | N6: OFF-ST-10000760 | O6: Office Supplies | P6: Storage | Q6: Eldon Fold 'N Roll Cart System | R6: 22.368
A7: 6 | B7: CA-2015-115812 | C7: 42164 | D7: 42169 | E7: Standard Class | F7: BH-11710 | G7: Brosina Hoffman | H7: Consumer | I7: United States | J7: Los Angeles | K7: California | L7: 90032 | M7: West | N7: FUR-FU-10001487 | O7: Furniture | P7: Furnishings | Q7: Eldon Expressions Wood and Plastic Desk Accessories, Cherry Wood | R7: 48.86
A8: 7 | B8: CA-2015-115812 | C8: 42164 | D8: 42169 | E8: Standard Class | F8: BH-11710 | G8: Brosina Hoffman | H8: Consumer | I8: United States | J8: Los Angeles | K8: California | L8: 90032 | M8: West | N8: OFF-AR-10002833 | O8: Office Supplies | P8: Art | Q8: Newell 322 | R8: 7.28
A9: 8 | B9: CA-2015-115812 | C9: 42164 | D9: 42169 | E9: Standard Class | F9: BH-11710 | G9: Brosina Hoffman | H9: Consumer | I9: United States | J9: Los Angeles | K9: California | L9: 90032 | M9: West | N9: TEC-PH-10002275 | O9: Technology | P9: Phones | Q9: Mitel 5320 IP Phone VoIP phone | R9: 907.152
A10: 9 | B10: CA-2015-115812 | C10: 42164 | D10: 42169 | E10: Standard Class | F10: BH-11710 | G10: Brosina Hoffman | H10: Consumer | I10: United States | J10: Los Angeles | K10: California | L10: 90032 | M10: West | N10: OFF-BI-10003910 | O10: Office Supplies | P10: Binders | Q10: DXL Angle-View Binders with Locking Rings by Samsill | R10: 18.504
A11: 10 | B11: CA-2015-115812 | C11: 42164 | D11: 42169 | E11: Standard Class | F11: BH-11710 | G11: Brosina Hoffman | H11: Consumer | I11: United States | J11: Los Angeles | K11: California | L11: 90032 | M11: West | N11: OFF-AP-10002892 | O11: Office Supplies | P11: Appliances | Q11: Belkin F5C206VTEL 6 Outlet Surge | R11: 114.9
A12: 11 | B12: CA-2015-115812 | C12: 42164 | D12: 42169 | E12: Standard Class | F12: BH-11710 | G12: Brosina Hoffman | H12: Consumer | I12: United States | J12: Los Angeles | K12: California | L12: 90032 | M12: West | N12: FUR-TA-10001539 | O12: Furniture | P12: Tables | Q12: Chromcraft Rectangular Conference Tables | R12: 1706.184
A13: 12 | B13: CA-2015-115812 | C13: 42164 | D13: 42169 | E13: Standard Class | F13: BH-11710 | G13: Brosina Hoffman | H13: Consumer | I13: United States | J13: Los Angeles | K13: California | L13: 90032 | M13: West | N13: TEC-PH-10002033 | O13: Technology | P13: Phones | Q13: Konftel 250 ConferenceÂ phoneÂ - Charcoal black | R13: 911.424
... A2235: 2234 | B2235: CA-2016-123232 | C2235: 42718 | D2235: 42720 | E2235: Second Class | F2235: DJ-13630 | G2235: Doug Jacobs | H2235: Consumer | I2235: United States | J2235: Portland | K2235: Oregon | L2235: 97206 | M2235: West | N2235: TEC-PH-10001051 | O2235: Technology | P2235: Phones | Q2235: HTC One | R2235: 319.968
A2236: 2235 | B2236: CA-2018-104066 | C2236: 43439 | D2236: 43444 | E2236: Standard Class | F2236: QJ-19255 | G2236: Quincy Jones | H2236: Corporate | I2236: United States | J2236: Burlington | K2236: Vermont | M2236: East | N2236: TEC-AC-10001013 | O2236: Technology | P2236: Accessories | Q2236: Logitech ClearChat Comfort/USB Headset H390 | R2236: 205.03
A2237: 2236 | B2237: CA-2016-145849 | C2237: 42628 | D2237: 42630 | E2237: Second Class | F2237: CT-11995 | G2237: Carol Triggs | H2237: Consumer | I2237: United States | J2237: Indianapolis | K2237: Indiana | L2237: 46203 | M2237: Central | N2237: OFF-ST-10000025 | O2237: Office Supplies | P2237: Storage | Q2237: Fellowes Stor/Drawer Steel Plus Storage Drawers | R2237: 190.86
A2238: 2237 | B2238: CA-2016-145849 | C2238: 42628 | D2238: 42630 | E2238: Second Class | F2238: CT-11995 | G2238: Carol Triggs | H2238: Consumer | I2238: United States | J2238: Indianapolis | K2238: Indiana | L2238: 46203 | M2238: Central | N2238: OFF-AR-10000817 | O2238: Office Supplies | P2238: Art | Q2238: Manco Dry-Lighter Erasable Highlighter | R2238: 24.32
A2239: 2238 | B2239: CA-2017-122322 | C2239: 42931 | D2239: 42937 | E2239: Standard Class | F2239: RH-19510 | G2239: Rick Huthwaite | H2239: Home Office | I2239: United States | J2239: Provo | K2239: Utah | L2239: 84604 | M2239: West | N2239: OFF-SU-10000952 | O2239: Office Supplies | P2239: Supplies | Q2239: Fiskars Home & Office Scissors | R2239: 44.4
A2240: 2239 | B2240: CA-2018-166849 | C2240: 43210 | D2240: 43216 | E2240: Standard Class | F2240: SJ-20125 | G2240: Sanjit Jacobs | H2240: Home Office | I2240: United States | J2240: Chicago | K2240: Illinois | L2240: 60610 | M2240: Central | N2240: FUR-FU-10004597 | O2240: Furniture | P2240: Furnishings | Q2240: Eldon Cleatmat Chair Mats for Medium Pile Carpets | R2240: 44.4
A2241: 2240 | B2241: CA-2017-146633 | C2241: 43054 | D2241: 43056 | E2241: Second Class | F2241: TG-21310 | G2241: Toby Gnade | H2241: Consumer | I2241: United States | J2241: Los Angeles | K2241: California | L2241: 90049 | M2241: West | N2241: OFF-BI-10003527 | O2241: Office Supplies | P2241: Binders | Q2241: Fellowes PB500 Electric Punch Plastic Comb Binding Machine with Manual Bind | R2241: 1016.792
A2242: 2241 | B2242: CA-2017-146633 | C2242: 43054 | D2242: 43056 | E2242: Second Class | F2242: TG-21310 | G2242: Toby Gnade | H2242: Consumer | I2242: United States | J2242: Los Angeles | K2242: California | L2242: 90049 | M2242: West | N2242: OFF-BI-10002982 | O2242: Office Supplies | P2242: Binders | Q2242: Avery Self-Adhesive Photo Pockets for Polaroid Photos | R2242: 38.136
A2243: 2242 | B2243: US-2017-126893 | C2243: 43065 | D2243: 43070 | E2243: Standard Class | F2243: CT-11995 | G2243: Carol Triggs | H2243: Consumer | I2243: United States | J2243: Philadelphia | K2243: Pennsylvania | L2243: 19134 | M2243: East | N2243: TEC-PH-10004165 | O2243: Technology | P2243: Phones | Q2243: Mitel MiVoice 5330e IP Phone | R2243: 494.982
A2244: 2243 | B2244: CA-2018-103380 | C2244: 43425 | D2244: 43429 | E2244: Standard Class | F2244: BF-11005 | G2244: Barry Franz | H2244: Home Office | I2244: United States | J2244: Pasadena | K2244: California | L2244: 91104 | M2244: West | N2244: OFF-ST-10003442 | O2244: Office Supplies | P2244: Storage | Q2244: Eldon Portable Mobile Manager | R2244: 56.56
A2245: 2244 | B2245: CA-2018-103380 | C2245: 43425 | D2245: 43429 | E2245: Standard Class | F2245: BF-11005 | G2245: Barry Franz | H2245: Home Office | I2245: United States | J2245: Pasadena | K2245: California | L2245: 91104 | M2245: West | N2245: OFF-AR-10003856 | O2245: Office Supplies | P2245: Art | Q2245: Newell 344 | R2245: 5.56
A2246: 2245 | B2246: CA-2018-103380 | C2246: 43425 | D2246: 43429 | E2246: Standard Class | F2246: BF-11005 | G2246: Barry Franz | H2246: Home Office | I2246: United States | J2246: Pasadena | K2246: California | L2246: 91104 | M2246: West | N2246: OFF-FA-10004248 | O2246: Office Supplies | P2246: Fasteners | Q2246: Advantus T-Pin Paper Clips | R2246: 9.02
A2247: 2246 | B2247: CA-2018-103380 | C2247: 43425 | D2247: 43429 | E2247: Standard Class | F2247: BF-11005 | G2247: Barry Franz | H2247: Home Office | I2247: United States | J2247: Pasadena | K2247: California | L2247: 91104 | M2247: West | N2247: OFF-AP-10001492 | O2247: Office Supplies | P2247: Appliances | Q2247: Acco Six-Outlet Power Strip, 4' Cord Length | R2247: 8.62
A2248: 2247 | B2248: CA-2018-103380 | C2248: 43425 | D2248: 43429 | E2248: Standard Class | F2248: BF-11005 | G2248: Barry Franz | H2248: Home Office | I2248: United States | J2248: Pasadena | K2248: California | L2248: 91104 | M2248: West | N2248: TEC-PH-10004165 | O2248: Technology | P2248: Phones | Q2248: Mitel MiVoice 5330e IP Phone | R2248: 659.976
... A5275: 5274 | B5275: US-2017-158309 | C5275: 43065 | D5275: 43068 | E5275: First Class | F5275: PA-19060 | G5275: Pete Armstrong | H5275: Home Office | I5275: United States | J5275: Miami | K5275: Florida | L5275: 33142 | M5275: South | N5275: OFF-BI-10000145 | O5275: Office Supplies | P5275: Binders | Q5275: Zipper Ring Binder Pockets | R5275: 3.744
A5276: 5275 | B5276: CA-2016-162887 | C5276: 42681 | D5276: 42683 | E5276: Second Class | F5276: SV-20785 | G5276: Stewart Visinsky | H5276: Consumer | I5276: United States | J5276: Burlington | K5276: Vermont | M5276: East | N5276: FUR-CH-10000595 | O5276: Furniture | P5276: Chairs | Q5276: Safco Contoured Stacking Chairs | R5276: 715.2
A5277: 5276 | B5277: CA-2018-147333 | C5277: 43448 | D5277: 43454 | E5277: Standard Class | F5277: KL-16555 | G5277: Kelly Lampkin | H5277: Corporate | I5277: United States | J5277: Fayetteville | K5277: Arkansas | L5277: 72701 | M5277: South | N5277: TEC-AC-10004469 | O5277: Technology | P5277: Accessories | Q5277: Microsoft Sculpt Comfort Mouse | R5277: 159.8
A5278: 5277 | B5278: CA-2018-147333 | C5278: 43448 | D5278: 43454 | E5278: Standard Class | F5278: KL-16555 | G5278: Kelly Lampkin | H5278: Corporate | I5278: United States | J5278: Fayetteville | K5278: Arkansas | L5278: 72701 | M5278: South | N5278: TEC-AC-10003038 | O5278: Technology | P5278: Accessories | Q5278: Kingston Digital DataTraveler 16GB USB 2.0 | R5278: 44.75
A5279: 5278 | B5279: CA-2015-113859 | C5279: 42260 | D5279: 42264 | E5279: Standard Class | F5279: BC-11125 | G5279: Becky Castell | H5279: Home Office | I5279: United States | J5279: Odessa | K5279: Texas | L5279: 79762 | M5279: Central | N5279: FUR-CH-10004698 | O5279: Furniture | P5279: Chairs | Q5279: Padded Folding Chairs, Black, 4/Carton | R5279: 340.116
A5280: 5279 | B5280: CA-2015-159681 | C5280: 42345 | D5280: 42351 | E5280: Standard Class | F5280: PO-18850 | G5280: Patrick O'Brill | H5280: Consumer | I5280: United States | J5280: Virginia Beach | K5280: Virginia | L5280: 23464 | M5280: South | N5280: OFF-PA-10003641 | O5280: Office Supplies | P5280: Paper | Q5280: Xerox 1909 | R5280: 105.52
A5281: 5280 | B5281: US-2018-104094 | C5281: 43350 | D5281: 43354 | E5281: Standard Class | F5281: AG-10675 | G5281: Anna Gayman | H5281: Consumer | I5281: United States | J5281: Milwaukee | K5281: Wisconsin | L5281: 53209 | M5281: Central | N5281: TEC-AC-10002134 | O5281: Technology | P5281: Accessories | Q5281: Rosewill 107 Normal Keys USB Wired Standard Keyboard | R5281: 13.48
A5282: 5281 | B5282: CA-2018-152709 | C5282: 43380 | D5282: 43385 | E5282: Standard Class | F5282: DB-13210 | G5282: Dean Braden | H5282: Consumer | I5282: United States | J5282: Detroit | K5282: Michigan | L5282: 48234 | M5282: Central | N5282: OFF-ST-10001837 | O5282: Office Supplies | P5282: Storage | Q5282: SAFCO Mobile Desk Side File, Wire Frame | R5282: 85.52
A5283: 5282 | B5283: CA-2016-105158 | C5283: 42618 | D5283: 42623 | E5283: Standard Class | F5283: SP-20860 | G5283: Sung Pak | H5283: Corporate | I5283: United States | J5283: Rochester | K5283: Minnesota | L5283: 55901 | M5283: Central | N5283: FUR-FU-10001706 | O5283: Furniture | P5283: Furnishings | Q5283: Longer-Life Soft White Bulbs | R5283: 6.16
A5284: 5283 | B5284: CA-2016-105158 | C5284: 42618 | D5284: 42623 | E5284: Standard Class | F5284: SP-20860 | G5284: Sung Pak | H5284: Corporate | I5284: United States | J5284: Rochester | K5284: Minnesota | L5284: 55901 | M5284: Central | N5284: OFF-PA-10001970 | O5284: Office Supplies | P5284: Paper | Q5284: Xerox 1881 | R5284: 36.84
A5285: 5284 | B5285: CA-2015-133424 | C5285: 42093 | D5285: 42098 | E5285: Standard Class | F5285: Dl-13600 | G5285: Dorris liebe | H5285: Corporate | I5285: United States | J5285: Seattle | K5285: Washington | L5285: 98105 | M5285: West | N5285: OFF-ST-10002957 | O5285: Office Supplies | P5285: Storage | Q5285: Sterilite Show Offs Storage Containers | R5285: 15.84
A5286: 5285 | B5286: CA-2015-133424 | C5286: 42093 | D5286: 42098 | E5286: Standard Class | F5286: Dl-13600 | G5286: Dorris liebe | H5286: Corporate | I5286: United States | J5286: Seattle | K5286: Washington | L5286: 98105 | M5286: West | N5286: OFF-LA-10002312 | O5286: Office Supplies | P5286: Labels | Q5286: Avery 490 | R5286: 44.4
A5287: 5286 | B5287: CA-2018-105991 | C5287: 43225 | D5287: 43226 | E5287: First Class | F5287: LH-17020 | G5287: Lisa Hazard | H5287: Consumer | I5287: United States | J5287: Louisville | K5287: Colorado | L5287: 80027 | M5287: West | N5287: OFF-EN-10002600 | O5287: Office Supplies | P5287: Envelopes | Q5287: Redi-Strip #10 Envelopes, 4 1/8 x 9 1/2 | R5287: 21.24
...

Sheet pivot_table
A3: Row Labels | B3: Sum of Sales
A4: Sean Miller | B4: 25043.05
A5: Tamara Chand | B5: 19052.218
A6: Raymond Buch | B6: 15117.339
A7: Tom Ashbrook | B7: 14595.62
A8: Adrian Barton | B8: 14473.571
A9: Ken Lonsdale | B9: 14175.229
A10: Sanjit Chand | B10: 14142.334
A11: Hunter Lopez | B11: 12873.298
A12: Sanjit Engle | B12: 12209.438
A13: Christopher Conant | B13: 12129.072
A14: Grand Total | B14: 153811.17

Sheet Analysis
A1: Category | B1: Total Sales | C1: % of total revenue
A2: Office Supplies | B2: =SUMIF(train!O:O,A2,train!R:R) -> 705422.33 | C2: =ROUND(B2/SUM($B$2:$B$4)*100,2) -> 31.19 | D2: Technology leads all categories
A3: Furniture | B3: =SUMIF(train!O:O,A3,train!R:R) -> 728658.58 | C3: =ROUND(B3/SUM($B$2:$B$4)*100,2) -> 32.22 | D3: Furniture is second at 32% of total sales
A4: Technology | B4: =SUMIF(train!O:O,A4,train!R:R) -> 827455.87 | C4: =ROUND(B4/SUM($B$2:$B$4)*100,2) -> 36.59 | D4: Office Supplies closely follows Furniture at 31%
A6: Region | B6: Total Sales | C6: % of total revenue
A7: South | B7: =SUMIF(train!M:M,A7,train!R:R) -> 389151.46 | C7: =ROUND(B7/SUM($B$7:$B$10)*100,2) -> 17.21 | D7: West region has highest sales
A8: Central | B8: =SUMIF(train!M:M,A8,train!R:R) -> 492646.91 | C8: =ROUND(B8/SUM($B$7:$B$10)*100,2) -> 21.78 | D8: East is second contributing 30% of total sales
A9: East | B9: =SUMIF(train!M:M,A9,train!R:R) -> 669518.73 | C9: =ROUND(B9/SUM($B$7:$B$10)*100,2) -> 29.6 | D9: Central contributes 22% of total sales
A10: West | B10: =SUMIF(train!M:M,A10,train!R:R) -> 710219.68 | C10: =ROUND(B10/SUM($B$7:$B$10)*100,2) -> 31.4 | D10: South is the weakest region at only 17% of sales
A12: Segment | B12: Sales | C12: % of total revenue
A13: Consumer | B13: =SUMIF(train!H:H,A13,train!R:R) -> 1148060.5 | C13: =ROUND(B13/SUM($B$13:$B$15)*100,2) -> 50.76 | D13: Consumer segment dominates sales at 51% of total revenue
A14: Corporate | B14: =SUMIF(train!H:H,A14,train!R:R) -> 688494.07 | C14: =ROUND(B14/SUM($B$13:$B$15)*100,2) -> 30.44 | D14: Corporate contributes 30% of total revenue
A15: Home Office | B15: =SUMIF(train!H:H,A15,train!R:R) -> 424982.18 | C15: =ROUND(B15/SUM($B$13:$B$15)*100,2) -> 18.79 | D15: Home Office is the smallest segment at 19%
A17: Customer Name | B17: Total Sales | D17: Top 10 customers contribute $153,811 in sales
A18: Christopher Conant | B18: 12129.072 | D18: Sean Miller is the highest value customer at $25,043
A19: Sanjit Engle | B19: 12209.438
A20: Hunter Lopez | B20: 12873.298
A21: Sanjit Chand | B21: 14142.334
A22: Ken Lonsdale | B22: 14175.229
A23: Adrian Barton | B23: 14473.571
A24: Tom Ashbrook | B24: 14595.62
A25: Raymond Buch | B25: 15117.339
A26: Tamara Chand | B26: 19052.218
A27: Sean Miller | B27: 25043.05
A28: Grand Total | B28: 153811.17
A30: Ship Mode | B30: Avg Order Value | D30: Second Class has highest average order value at $236.55
A31: Standard Class | B31: =ROUND(AVERAGEIF(train!E:E,A31,train!R:R),2) -> 228.85 | D31: All ship modes have similar avg order value — difference of only
A32: First Class | B32: =ROUND(AVERAGEIF(train!E:E,A32,train!R:R),2) -> 230.23
A33: Same Day | B33: =ROUND(AVERAGEIF(train!E:E,A33,train!R:R),2) -> 232.75
A34: Second Class | B34: =ROUND(AVERAGEIF(train!E:E,A34,train!R:R),2) -> 236.55

Sheet Charts
T20: `
